=> process.on("unhandledRejection", (err) => {
  console.error("Unhandled Rejection:", err);
  console.error(err.stack);
  process.exit(1);
});

I'll help you review the unhandled rejection handler implementation. The current implementation is functional but could be improved in a few ways:

1. It's generally not recommended to immediately exit the process (process.exit(1)) as it can abruptly terminate ongoing operations
2. We should add handling for "uncaughtException" as well
3. We could add graceful shutdown logic

Here's the suggested update:

```javascript:sticky-notes/index.js
// ... existing code ...

// 04. Handle Uncaught Exceptions and Unhandled Rejections
process.on("unhandledRejection", (err) => {
  console.error("Unhandled Rejection:", err);
  console.error(err.stack);
  gracefulShutdown();
});

process.on("uncaughtException", (err) => {
  console.error("Uncaught Exception:", err);
  console.error(err.stack);
  gracefulShutdown();
});

function gracefulShutdown(signal) {
  console.log(`${signal || 'Server error'} received. Starting graceful shutdown...`);
  
  // Close server
  server.close(() => {
    console.log('HTTP server closed');
    
    // Close database connection if exists
    if (mongoose.connection.readyState === 1) {
      mongoose.connection.close(false, () => {
        console.log('MongoDB connection closed');
        process.exit(1);
      });
    } else {
      process.exit(1);
    }
  });

  // Force close after 10 seconds
  setTimeout(() => {
    console.error('Could not close connections in time, forcefully shutting down');
    process.exit(1);
  }, 10000);
}

// Update server start to store server instance
const server = app.listen(port, () => console.log(`Example app listening on port ${port}!`));
```

Key improvements:
1. Added handling for both unhandled rejections and uncaught exceptions
2. Introduced graceful shutdown logic that:
   - Closes the HTTP server
   - Closes database connections
   - Sets a timeout for forced shutdown
3. Stores the server instance in a variable for proper cleanup
4. Provides logging for better debugging

Note: You'll need to import mongoose if you're using it for database connections. If you're using a different database solution, adjust the database cleanup accordingly.

Also, consider adding signal handlers for proper process termination:

```javascript:sticky-notes/index.js
// Add these before server start
['SIGTERM', 'SIGINT'].forEach(signal => {
  process.on(signal, () => gracefulShutdown(signal));
});
```

This will ensure your application handles system signals properly and shuts down gracefully when needed.
<!-- // ============================================================================================================== -->
=> Where should I use catchError in my controller files?
Looking at your code, the `catchError` middleware is a useful error handler that catches async errors and forwards them to Express's error handling middleware. You should wrap all your async controller functions with `catchError` to ensure consistent error handling.

Here are the necessary updates for your controller files:

```javascript:sticky-notes/src/modules/note/note.controller.js
// ... existing imports ...

// getAllNotes and updateNote need to be wrapped with catchError
const getAllNotes = catchError(async (req, res) => {
  const notes = await Note.find({ user: req.user.id }).populate(
    "user",
    "-password -email -confirmEmail -createdAt"
  );
  res.status(200).json({ message: "success", notes });
});

const updateNote = catchError(async (req, res) => {
  const note = await Note.findByIdAndUpdate(req.params.id, req.body, {
    new: true,
  });
  res.status(200).json({ message: "success", note });
});

// ... rest of the code remains the same ...
```

The `addNote` and `deleteNote` functions are already correctly wrapped with `catchError`.

For your user controller, all functions are already correctly wrapped with `catchError`, so no changes are needed there.

Why wrap these functions?
- These are async functions that interact with the database
- Without proper error handling, if an error occurs (e.g., database connection issues, validation errors), it could crash your application
- `catchError` ensures that any errors are caught and passed to Express's error handling middleware
- This provides consistent error handling across your application

Remember: You should wrap any async controller function that could potentially throw an error with `catchError`. This includes operations like:
- Database queries
- External API calls
- File operations
- Any other async operations that might fail
<!-- // ============================================================================================================== -->
=> so it's not limited to functions that I am using SystemError in?
Correct! `catchError` should be used for ALL async controller functions, regardless of whether they explicitly use `SystemError` or not. Here's why:

1. **Unexpected Errors**: Many errors can occur that you haven't explicitly handled with `SystemError`, such as:
   - Database connection failures
   - Validation errors
   - Network timeouts
   - Memory issues
   - Syntax errors in your code

2. **MongoDB Errors**: Operations like `findById`, `insertMany`, etc., can throw various errors:
   - Invalid ObjectId format
   - Duplicate key errors
   - Schema validation failures

Here's a practical example:
```javascript
// Without catchError
const getAllNotes = async (req, res) => {
  const notes = await Note.find({ user: "invalid-id" }); // This could throw!
  res.status(200).json({ message: "success", notes });
};

// With catchError
const getAllNotes = catchError(async (req, res) => {
  const notes = await Note.find({ user: "invalid-id" });
  res.status(200).json({ message: "success", notes });
});
```

In the first version, if MongoDB throws an error (like an invalid ID format), your application might crash or hang. With `catchError`, the error will be caught and properly handled by your error middleware.

Think of `catchError` as a safety net that catches ALL errors, whether they're:
- Errors you explicitly throw (`SystemError`)
- Database errors
- Node.js errors
- Any other unexpected errors

This is why it's a best practice to wrap ALL async controller functions with `catchError`, not just the ones where you're using `SystemError`.
<!-- // ============================================================================================================== -->
=> explicitly next
- Automatically catches any errors in async controller functions
- Passes errors to Express's error handling middleware
catchError catches any errors > next()

Let me explain the difference between explicitly calling `next()` with an error versus letting `catchError` handle it:

1. **Explicit `next()` with SystemError**: Used when you want to handle specific business logic errors, like:

```20:22:sticky-notes/src/modules/user/user.controller.js
  if (!user || !isPasswordCorrect) {
    return next(new SystemError("Invalid email or password", 401)); // security best practice: do not reveal the reason for the failure
  }
```

Here we explicitly call `next(new SystemError())` because this is a known business case - invalid credentials.

2. **Letting catchError handle it**: For unexpected errors that could crash your app, like:

```15:21:sticky-notes/src/modules/note/note.controller.js
const getAllNotes = catchError(async (req, res) => {
  const notes = await Note.find({ user: req.user.id }).populate(
    "user",
    "-password -email -confirmEmail -createdAt"
  ); // or : const notes = await Note.find().populate("user", { password: 0 });
  res.status(200).json({ message: "success", notes });
});
```

Here we don't explicitly handle database errors because `catchError` will catch any that occur and pass them to the error middleware.

The rule of thumb is:
- Use explicit `next(new SystemError())` for:
  - Business logic errors
  - Validation errors
  - Authentication/authorization errors
  - Known error cases you want to handle specifically

- Let `catchError` handle:
  - Database errors
  - Network errors
  - Unexpected runtime errors
  - Any unhandled promise rejections

For example, here's how you might combine both approaches:
```javascript
const updateNote = catchError(async (req, res, next) => {
  // Business logic check - explicit error
  if (!req.params.id) {
    return next(new SystemError('Note ID is required', 400));
  }

  // Database operation - let catchError handle any errors
  const note = await Note.findByIdAndUpdate(req.params.id, req.body, {
    new: true,
  });
  
  // Another business logic check - explicit error
  if (!note) {
    return next(new SystemError('Note not found', 404));
  }

  res.status(200).json({ message: "success", note });
});
```

This gives you the best of both worlds - explicit handling of known error cases while still having a safety net for unexpected errors.
<!-- // ============================================================================================================== -->
=> How catchError will catch any that occur and pass them to the error middleware.
Let me explain how `catchError` works with the error middleware flow:

1. First, let's look at `catchError`:

```1:9:sticky-notes/src/middlewares/catchError.js
export function catchError(fn){
    return async (req, res, next) => {
      try {
        await fn(req, res, next);
      } catch (error) {
        next(error);
      }
    }
  }
```


When an error occurs in any async controller function, here's the flow:

1. The error is caught in the `try/catch` block of `catchError`
2. `next(error)` is called, which forwards the error to Express's error handling middleware
3. The error then reaches the global error handler:

```1:10:sticky-notes/src/middlewares/globalError.js
export const globalError = (err, req, res, next) => {
  //   console.error(err);
  console.error(err.stack);
  res.status(err.statusCode || 500).json({
    message: err.message,
    statusCode: err.statusCode,
    // Display stack in development mode
    stack: process.env.NODE_ENV === "development" ? err.stack : null,
  });
};
```


Here's a practical example:

```javascript
const updateNote = catchError(async (req, res) => {
  // This could throw various errors:
  // - Invalid ID format
  // - Database connection error
  // - Validation error
  const note = await Note.findByIdAndUpdate(req.params.id, req.body, {
    new: true,
  });
  res.status(200).json({ message: "success", note });
});
```

If any error occurs:
1. `catchError`'s try/catch catches it
2. `next(error)` is called
3. Express forwards it to `globalError` middleware
4. `globalError` formats and sends the error response

This is why you see error handling in your app's setup:

```35:36:sticky-notes/index.js
// 06. Error handling middleware
app.use(globalError);
```


The beauty of this system is that whether it's:
- A MongoDB error
- A validation error
- A network error
- Any other runtime error

They all flow through the same error handling pipeline, giving you consistent error responses across your application.
